<?xml version="1.0" ?>
<!-- =================================================================================== -->
<!-- |    This document was autogenerated by xacro from /home/gauss/projects/personal_ws/src/nj_220_2_7/nj_220_2_7_description/urdf/nj_220_2_7_alone.xacro | -->
<!-- |    EDITING THIS FILE BY HAND IS NOT RECOMMENDED                                 | -->
<!-- =================================================================================== -->
<robot name="nj_220_2_7">
    <link name="world" />
    <!--  195°/s -->
    <link name="base_link">
        <inertial>
            <origin rpy="0 0 0" xyz="0.035817 -0.1978 -1.2121E-05" />
            <mass value="780.97" />
            <inertia ixx="25.789" ixy="-0.0076742" ixz="0.0023584" iyy="48.078" iyz="2.5193E-05" izz="33.648" />
        </inertial>
        <visual>
            <origin rpy="0 0 0" xyz="0 0 0" />
            <geometry>
                <mesh filename="package://nj_220_2_7_gazebo/meshes/base_link.STL" />
            </geometry>
            <material name="">
                <color rgba="1 0 0 1" />
            </material>
        </visual>
        <collision>
            <origin rpy="0 0 0" xyz="0 0 0" />
            <geometry>
                <mesh filename="package://nj_220_2_7_gazebo/meshes/base_link.STL" />
            </geometry>
        </collision>
    </link>
    <link name="link_1">
        <inertial>
            <origin rpy="0 0 0" xyz="-0.28012 0.38938 0.024882" />
            <mass value="660.35" />
            <inertia ixx="38.274" ixy="9.9756" ixz="-0.5181" iyy="36.77" iyz="0.16531" izz="32.584" />
        </inertial>
        <visual>
            <origin rpy="0 0 0" xyz="0 0 0" />
            <geometry>
                <mesh filename="package://nj_220_2_7_gazebo/meshes/link_1.STL" />
            </geometry>
            <material name="">
                <color rgba="1 0 0 1" />
            </material>
        </visual>
        <collision>
            <origin rpy="0 0 0" xyz="0 0 0" />
            <geometry>
                <mesh filename="package://nj_220_2_7_gazebo/meshes/link_1.STL" />
            </geometry>
        </collision>
    </link>
    <joint name="joint_1" type="revolute">
        <origin rpy="1.570796327 0 0" xyz="0 0 0.331" />
        <parent link="base_link" />
        <child link="link_1" />
        <axis xyz="0 1 0" />
        <limit effort="10000" lower="-1.570796327" upper="1.570796327" velocity="1.74533" />
    </joint>
    <link name="link_2">
        <inertial>
            <origin rpy="0 0 0" xyz="0.018416 0.51384 0.098759" />
            <mass value="120.34" />
            <inertia ixx="21.96" ixy="-0.10832" ixz="-0.0016497" iyy="2.2176" iyz="-0.46644" izz="21.671" />
        </inertial>
        <visual>
            <origin rpy="0 0 0" xyz="0 0 0" />
            <geometry>
                <mesh filename="package://nj_220_2_7_gazebo/meshes/link_2.STL" />
            </geometry>
            <material name="">
                <color rgba="1 0 0 1" />
            </material>
        </visual>
        <collision>
            <origin rpy="0 0 0" xyz="0 0 0" />
            <geometry>
                <mesh filename="package://nj_220_2_7_gazebo/meshes/link_2.STL" />
            </geometry>
        </collision>
    </link>
    <joint name="joint_2" type="revolute">
        <origin rpy="3.1416 0 -3.1416" xyz="-0.4 0.499 0.0955" />
        <parent link="link_1" />
        <child link="link_2" />
        <axis xyz="0 0 -1" />
        <limit effort="10000" lower="-1.308996939" upper="1.658062789" velocity="1.5708" />
    </joint>
    <link name="link_3">
        <inertial>
            <origin rpy="0 0 0" xyz="0.09381 0.22038 0.04158" />
            <mass value="387.8" />
            <inertia ixx="11.134" ixy="0.24648" ixz="-0.33063" iyy="8.7654" iyz="-1.165" izz="7.1302" />
        </inertial>
        <visual>
            <origin rpy="0 0 0" xyz="0 0 0" />
            <geometry>
                <mesh filename="package://nj_220_2_7_gazebo/meshes/link_3.STL" />
            </geometry>
            <material name="">
                <color rgba="1 0 0 1" />
            </material>
        </visual>
        <collision>
            <origin rpy="0 0 0" xyz="0 0 0" />
            <geometry>
                <mesh filename="package://nj_220_2_7_gazebo/meshes/link_3.STL" />
            </geometry>
        </collision>
    </link>
    <joint name="joint_3" type="revolute">
        <origin rpy="0 0 0" xyz="0 0 0" />
        <parent link="link_3_virtual" />
        <child link="link_3" />
        <axis xyz="0 0 -1" />
        <limit effort="10000" lower="-4.468042885" upper="0.174532925" velocity="1.91986" />
    </joint>
    <link name="link_4">
        <inertial>
            <origin rpy="0 0 0" xyz="-2.6683E-05 0.025673 0.71228" />
            <mass value="90.963" />
            <inertia ixx="3.6809" ixy="-0.0002411" ixz="0.00016385" iyy="3.6011" iyz="-0.16069" izz="0.59075" />
        </inertial>
        <visual>
            <origin rpy="0 0 0" xyz="0 0 0" />
            <geometry>
                <mesh filename="package://nj_220_2_7_gazebo/meshes/link_4.STL" />
            </geometry>
            <material name="">
                <color rgba="1 0 0 1" />
            </material>
        </visual>
        <collision>
            <origin rpy="0 0 0" xyz="0 0 0" />
            <geometry>
                <mesh filename="package://nj_220_2_7_gazebo/meshes/link_4.STL" />
            </geometry>
        </collision>
    </link>
    <joint name="joint_4" type="revolute">
        <origin rpy="-1.5708 -0.045821 1.5708" xyz="-0.105 0.25 0" />
        <parent link="link_3" />
        <child link="link_4" />
        <axis xyz="0 0 1" />
        <limit effort="1230" lower="-6.2831853" upper="6.2831853" velocity="2.26893" />
    </joint>
    <link name="link_5">
        <inertial>
            <origin rpy="0 0 0" xyz="-0.090754 0.11294 2.4961E-05" />
            <mass value="50.615" />
            <inertia ixx="0.66826" ixy="0.026389" ixz="-1.8609E-05" iyy="0.3874" iyz="9.9459E-05" izz="0.86592" />
        </inertial>
        <visual>
            <origin rpy="0 0 0" xyz="0 0 0" />
            <geometry>
                <mesh filename="package://nj_220_2_7_gazebo/meshes/link_5.STL" />
            </geometry>
            <material name="">
                <color rgba="1 0 0 1" />
            </material>
        </visual>
        <collision>
            <origin rpy="0 0 0" xyz="0 0 0" />
            <geometry>
                <mesh filename="package://nj_220_2_7_gazebo/meshes/link_5.STL" />
            </geometry>
        </collision>
    </link>
    <joint name="joint_5" type="revolute">
        <origin rpy="0 1.5708 0" xyz="0 -0.128 1.0233" />
        <parent link="link_4" />
        <child link="link_5" />
        <axis xyz="0 1 0" />
        <limit effort="1230" lower="-2.1816" upper="2.1816" velocity="2.26893" />
    </joint>
    <link name="link_6">
        <inertial>
            <origin rpy="0 0 0" xyz="-0.0058594 0.00060952 -5.99E-05" />
            <mass value="5.3437" />
            <inertia ixx="0.029134" ixy="-1.0867E-05" ixz="1.1966E-06" iyy="0.015147" iyz="5.6576E-06" izz="0.015003" />
        </inertial>
        <visual>
            <origin rpy="0 0 0" xyz="0 0 0" />
            <geometry>
                <mesh filename="package://nj_220_2_7_gazebo/meshes/link_6.STL" />
            </geometry>
            <material name="">
                <color rgba="0.25098 0.25098 0.25098 1" />
            </material>
        </visual>
        <collision>
            <origin rpy="0 0 0" xyz="0 0 0" />
            <geometry>
                <mesh filename="package://nj_220_2_7_gazebo/meshes/link_6.STL" />
            </geometry>
        </collision>
    </link>
    <joint name="joint_6" type="revolute">
        <origin rpy="-0.045821 0 0" xyz="-0.2055 0.128 0" />
        <parent link="link_5" />
        <child link="link_6" />
        <axis xyz="-1 0 0" />
        <limit effort="712" lower="-6.2831853" upper="6.2831853" velocity="3.40339" />
    </joint>
    <!-- Parallel Linkages  -->
    <link name="link_3_virtual" />
    <joint name="joint_2m" type="continuous">
        <origin rpy="3.1416 0 -1.5708" xyz="0 1.175 0.0955" />
        <parent link="link_2" />
        <child link="link_3_virtual" />
        <axis xyz="0 0 -1" />
        <mimic joint="joint_2" multiplier="1" offset="-1.570796326794897" />
    </joint>
    <link name="link_2_1">
        <inertial>
            <origin rpy="0 0 0" xyz="0.14943 -0.0063786 0.023924" />
            <mass value="41.905" />
            <inertia ixx="0.15952" ixy="0.030699" ixz="-0.02238" iyy="0.74929" iyz="0.0001768" izz="0.83836" />
        </inertial>
        <visual>
            <origin rpy="0 0 0" xyz="0 0 0" />
            <geometry>
                <mesh filename="package://nj_220_2_7_gazebo/meshes/link_2_1.STL" />
            </geometry>
            <material name="">
                <color rgba="1 0 0 1" />
            </material>
        </visual>
        <collision>
            <origin rpy="0 0 0" xyz="0 0 0" />
            <geometry>
                <mesh filename="package://nj_220_2_7_gazebo/meshes/link_2_1.STL" />
            </geometry>
        </collision>
    </link>
    <joint name="joint_2_1" type="continuous">
        <origin rpy="0 0 -0.087266" xyz="-0.4 0.499 -0.1945" />
        <parent link="link_1" />
        <child link="link_2_1" />
        <axis xyz="0 0 -1" />
        <mimic joint="joint_3" multiplier="1" offset="0" />
    </joint>
    <link name="link_2_2_virtual" />
    <joint name="joint_2_2" type="continuous">
        <origin rpy="0 0 0.08723" xyz="0.35 0 0.015" />
        <parent link="link_2_1" />
        <child link="link_2_2_virtual" />
        <axis xyz="0 0 1" />
        <mimic joint="joint_3" multiplier="1" offset="0" />
    </joint>
    <link name="link_2_2">
        <inertial>
            <origin rpy="0 0 0" xyz="0.064434 0.51885 0.014848" />
            <mass value="60.719" />
            <inertia ixx="5.5799" ixy="0.13804" ixz="0.0007529" iyy="0.14481" iyz="-0.0028767" izz="5.6722" />
        </inertial>
        <visual>
            <origin rpy="0 0 0" xyz="0 0 0" />
            <geometry>
                <mesh filename="package://nj_220_2_7_gazebo/meshes/link_2_2.STL" />
            </geometry>
            <material name="">
                <color rgba="1 0 0 1" />
            </material>
        </visual>
        <collision>
            <origin rpy="0 0 0" xyz="0 0 0" />
            <geometry>
                <mesh filename="package://nj_220_2_7_gazebo/meshes/link_2_2.STL" />
            </geometry>
        </collision>
    </link>
    <joint name="joint_2_3" type="continuous">
        <origin rpy="0 0 0" xyz="0.0 0.0 0.0" />
        <parent link="link_2_2_virtual" />
        <child link="link_2_2" />
        <axis xyz="0 0 -1" />
        <mimic joint="joint_2" multiplier="-1" offset="0" />
    </joint>
    <!-- End Parallel Linkages -->
    <link name="flange">
        <inertial>
            <origin rpy="0 0 0" xyz="0 0 0" />
            <mass value="0.01" />
            <inertia ixx="0.00001" ixy="0.00000" ixz="0.00000" iyy="0.00001" iyz="0.00000" izz="0.00000" />
        </inertial>
    </link>
    <joint name="link_6_to_flange" type="fixed">
        <origin rpy="3.1416 0 -1.5708" xyz="0 0 -0.0395" />
        <parent link="link_6" />
        <child link="flange" />
        <axis xyz="0 0 0" />
    </joint>
    <transmission name="tran_1">
        <type>transmission_interface/SimpleTransmission</type>
        <joint name="joint_1">
            <hardwareInterface>hardware_interface/EffortJointInterface</hardwareInterface>
        </joint>
        <actuator name="motor_1">
            <mechanicalReduction>1</mechanicalReduction>
            <hardwareInterface>hardware_interface/EffortJointInterface</hardwareInterface>
        </actuator>
    </transmission>
    <transmission name="tran_2">
        <type>transmission_interface/SimpleTransmission</type>
        <joint name="joint_2">
            <hardwareInterface>hardware_interface/EffortJointInterface</hardwareInterface>
        </joint>
        <actuator name="motor_2">
            <mechanicalReduction>1</mechanicalReduction>
            <hardwareInterface>hardware_interface/EffortJointInterface</hardwareInterface>
        </actuator>
    </transmission>
    <transmission name="tran_3">
        <type>transmission_interface/SimpleTransmission</type>
        <joint name="joint_3">
            <hardwareInterface>hardware_interface/EffortJointInterface</hardwareInterface>
        </joint>
        <actuator name="motor_3">
            <mechanicalReduction>1</mechanicalReduction>
            <hardwareInterface>hardware_interface/EffortJointInterface</hardwareInterface>
        </actuator>
    </transmission>
    <transmission name="tran_4">
        <type>transmission_interface/SimpleTransmission</type>
        <joint name="joint_4">
            <hardwareInterface>hardware_interface/EffortJointInterface</hardwareInterface>
        </joint>
        <actuator name="motor_4">
            <mechanicalReduction>1</mechanicalReduction>
            <hardwareInterface>hardware_interface/EffortJointInterface</hardwareInterface>
        </actuator>
    </transmission>
    <transmission name="tran_5">
        <type>transmission_interface/SimpleTransmission</type>
        <joint name="joint_5">
            <hardwareInterface>hardware_interface/EffortJointInterface</hardwareInterface>
        </joint>
        <actuator name="motor_5">
            <mechanicalReduction>1</mechanicalReduction>
            <hardwareInterface>hardware_interface/EffortJointInterface</hardwareInterface>
        </actuator>
    </transmission>
    <transmission name="tran_6">
        <type>transmission_interface/SimpleTransmission</type>
        <joint name="joint_6">
            <hardwareInterface>hardware_interface/EffortJointInterface</hardwareInterface>
        </joint>
        <actuator name="motor_6">
            <mechanicalReduction>1</mechanicalReduction>
            <hardwareInterface>hardware_interface/EffortJointInterface</hardwareInterface>
        </actuator>
    </transmission>
    <gazebo>
        <plugin filename="libgazebo_ros_control.so" name="gazebo_ros_control">
            <robotNamespace>/nj_220_2_7</robotNamespace>
            <robotSimType>gazebo_ros_control/DefaultRobotHWSim</robotSimType>
        </plugin>
    </gazebo>
    <gazebo>
        <plugin filename="libroboticsgroup_gazebo_mimic_joint_plugin.so" name="joint_2mmimic_joint_plugin">
            <joint>joint_2</joint>
            <mimicJoint>joint_2m</mimicJoint>
            <multiplier>1.0</multiplier>
            <offset>0</offset>
            <sensitiveness>0.0</sensitiveness>
            <maxEffort>10.0</maxEffort>
        </plugin>
    </gazebo>
    --&gt;
    <!--Mimic Joint Plug in for Gazebo-->
    <gazebo reference="link_6_to_flange">
        <provideFeedback>true</provideFeedback>
        <disableFixedJointLumping>true</disableFixedJointLumping>
        <preserveFixedJoint>true</preserveFixedJoint>
    </gazebo>
    <gazebo>
        <plugin filename="libgazebo_ros_ft_sensor.so" name="ft_sensor">
            <updateRate>1000.0</updateRate>
            <topicName>gripper/wrench</topicName>
            <jointName>link_6_to_flange</jointName>
        </plugin>
    </gazebo>
    <joint name="world_to_base_link" type="fixed">
        <origin rpy="0 0 0" xyz="0 0 0" />
        <!-- rpy="-1.57079632679 0 0" /> -->
        <parent link="world" />
        <child link="base_link" />
    </joint>
    <transmission name="trans_joint_2m">
        <type>transmission_interface/SimpleTransmission</type>
        <joint name="joint_2m">
            <hardwareInterface>hardware_interface/EffortJointInterface</hardwareInterface>
        </joint>
        <actuator name="joint_2m_motor">
            <hardwareInterface>hardware_interface/EffortJointInterface</hardwareInterface>
            <mechanicalReduction>1</mechanicalReduction>
        </actuator>
    </transmission>
    <transmission name="trans_joint_2_1">
        <type>transmission_interface/SimpleTransmission</type>
        <joint name="joint_2_1">
            <hardwareInterface>hardware_interface/EffortJointInterface</hardwareInterface>
        </joint>
        <actuator name="joint_2_1_motor">
            <hardwareInterface>hardware_interface/EffortJointInterface</hardwareInterface>
            <mechanicalReduction>1</mechanicalReduction>
        </actuator>
    </transmission>
    <transmission name="trans_joint_2_2">
        <type>transmission_interface/SimpleTransmission</type>
        <joint name="joint_2_2">
            <hardwareInterface>hardware_interface/EffortJointInterface</hardwareInterface>
        </joint>
        <actuator name="joint_2_2_motor">
            <hardwareInterface>hardware_interface/EffortJointInterface</hardwareInterface>
            <mechanicalReduction>1</mechanicalReduction>
        </actuator>
    </transmission>
    <transmission name="trans_joint_2_3">
        <type>transmission_interface/SimpleTransmission</type>
        <joint name="joint_2_3">
            <hardwareInterface>hardware_interface/EffortJointInterface</hardwareInterface>
        </joint>
        <actuator name="joint_2_3_motor">
            <hardwareInterface>hardware_interface/EffortJointInterface</hardwareInterface>
            <mechanicalReduction>1</mechanicalReduction>
        </actuator>
    </transmission>
</robot>

