<?xml version="1.0" ?>
<!-- =================================================================================== -->
<!-- |    This document was autogenerated by xacro from /home/gauss/projects/personal_ws/src/nj_220_2_7/nj_220_2_7_description/urdf/nj_220_2_7_alone.xacro | -->
<!-- |    EDITING THIS FILE BY HAND IS NOT RECOMMENDED                                 | -->
<!-- =================================================================================== -->
<robot name="nj_220_2_7">
    <link name="world" />
    <!--  195°/s -->
    <link name="base_link">
        <inertial>
            <origin rpy="0 0 0" xyz="0.035817 -0.00001 0.13320" />
            <mass value="780.97" />
            <inertia ixx="39.64573032" ixy="0.00269524" ixz="-3.73357627" iyy="48.50586929" iyz="-0.00127807" izz="49.079656" />
        </inertial>
        <visual>
            <origin rpy="0 0 0" xyz="0 0 0" />
            <geometry>
                <mesh filename="package://nj_220_2_7_gazebo/meshes/base_link.STL" />
            </geometry>
            <material name="">
                <color rgba="1 0 0 1" />
            </material>
        </visual>
        <collision>
            <origin rpy="0 0 0" xyz="0 0 0" />
            <geometry>
                <mesh filename="package://nj_220_2_7_gazebo/meshes/base_link.STL" />
            </geometry>
        </collision>
    </link>
    <link name="link_1">
        <inertial>
            <origin rpy="0 0 0" xyz="0.31397 0.02536 0.37802" />
            <mass value="120.57" />
            <inertia ixx="96.14944607" ixy="2.82831578" ixz="59.92048931" iyy="132.52767347" iyz="3.87136939" izz="76.40305744" />
        </inertial>
        <visual>
            <origin rpy="0 0 0" xyz="0 0 0" />
            <geometry>
                <mesh filename="package://nj_220_2_7_gazebo/meshes/link_1.STL" />
            </geometry>
            <material name="">
                <color rgba="1 0 0 1" />
            </material>
        </visual>
        <collision>
            <origin rpy="0 0 0" xyz="0 0 0" />
            <geometry>
                <mesh filename="package://nj_220_2_7_gazebo/meshes/link_1.STL" />
            </geometry>
        </collision>
    </link>
    <joint name="joint_1" type="revolute">
        <origin rpy="0 0 0" xyz="0 0 0.331" />
        <parent link="base_link" />
        <child link="link_1" />
        <axis xyz="0 0 1" />
        <limit effort="100000" lower="-1.570796327" upper="1.570796327" velocity="1.74533" />
    </joint>
    <link name="link_2">
        <inertial>
            <origin rpy="0 0 0" xyz="0.018416 -0.00326 0.51384" />
            <mass value="120.34" />
            <inertia ixx="53.73638778" ixy="-0.00887173" ixz="1.24711967" iyy="53.48705119" iyz="-0.66793611" izz="2.25971599" />
        </inertial>
        <visual>
            <origin rpy="0 0 0" xyz="0 0 0" />
            <geometry>
                <mesh filename="package://nj_220_2_7_gazebo/meshes/link_2.STL" />
            </geometry>
            <material name="">
                <color rgba="1 0 0 1" />
            </material>
        </visual>
        <collision>
            <origin rpy="0 0 0" xyz="0 0 0" />
            <geometry>
                <mesh filename="package://nj_220_2_7_gazebo/meshes/link_2.STL" />
            </geometry>
        </collision>
    </link>
    <joint name="joint_2" type="revolute">
        <origin rpy="0 0 0" xyz="0.4 0 0.499" />
        <parent link="link_1" />
        <child link="link_2" />
        <axis xyz="0 1 0" />
        <limit effort="100000" lower="-1.308996939" upper="1.658062789" velocity="1.5708" />
    </joint>
    <link name="link_3">
        <inertial>
            <origin rpy="0 0 0" xyz="-0.04239 0.01939 0.2104" />
            <mass value="303.81" />
            <inertia ixx="24.45402173" ixy="-0.58037596" ixz="-2.46563321" iyy="20.71802091" iyz="2.40454026" izz="9.01610712" />
        </inertial>
        <visual>
            <origin rpy="0 0 0" xyz="0 0 0" />
            <geometry>
                <mesh filename="package://nj_220_2_7_gazebo/meshes/link_3.STL" />
            </geometry>
            <material name="">
                <color rgba="1 0 0 1" />
            </material>
        </visual>
        <collision>
            <origin rpy="0 0 0" xyz="0 0 0" />
            <geometry>
                <mesh filename="package://nj_220_2_7_gazebo/meshes/link_3.STL" />
            </geometry>
        </collision>
    </link>
    <joint name="joint_3" type="revolute">
        <origin rpy="0 0 0" xyz="0 0 0" />
        <parent link="link_3_virtual" />
        <child link="link_3" />
        <axis xyz="0 -1 0" />
        <limit effort="100000" lower="-4.468042885" upper="0.174532925" velocity="1.91986" />
    </joint>
    <link name="link_4">
        <inertial>
            <origin rpy="0 0 0" xyz="0.71228 -0.02567 -0.00003" />
            <mass value="90.963" />
            <inertia ixx="0.68929228290" ixy="-2.39235486446" ixz="-0.00192589885" iyy="58.11987131958" iyz="-0.00017654018" izz="58.29818388998" />
        </inertial>
        <visual>
            <origin rpy="0 0 0" xyz="0 0 0" />
            <geometry>
                <mesh filename="package://nj_220_2_7_gazebo/meshes/link_4.STL" />
            </geometry>
            <material name="">
                <color rgba="1 0 0 1" />
            </material>
        </visual>
        <collision>
            <origin rpy="0 0 0" xyz="0 0 0" />
            <geometry>
                <mesh filename="package://nj_220_2_7_gazebo/meshes/link_4.STL" />
            </geometry>
        </collision>
    </link>
    <joint name="joint_4" type="revolute">
        <origin rpy="0 0 0" xyz="0.105 0 0.25" />
        <parent link="link_3" />
        <child link="link_4" />
        <axis xyz="1 0 0" />
        <limit effort="1230" lower="-6.2831853" upper="6.2831853" velocity="2.26893" />
    </joint>
    <link name="link_5">
        <inertial>
            <origin rpy="0 0 0" xyz="0.09375 0.01506 0.00002" />
            <mass value="50.615" />
            <inertia ixx="0.67974396" ixy="0.04508972" ixz="0.00009980" iyy="0.83229961" iyz="0.00011851" izz="1.32231171" />
        </inertial>
        <visual>
            <origin rpy="0 0 0" xyz="0 0 0" />
            <geometry>
                <mesh filename="package://nj_220_2_7_gazebo/meshes/link_5.STL" />
            </geometry>
            <material name="">
                <color rgba="1 0 0 1" />
            </material>
        </visual>
        <collision>
            <origin rpy="0 0 0" xyz="0 0 0" />
            <geometry>
                <mesh filename="package://nj_220_2_7_gazebo/meshes/link_5.STL" />
            </geometry>
        </collision>
    </link>
    <joint name="joint_5" type="revolute">
        <origin rpy="0 0 0" xyz="1.02033 0 0" />
        <parent link="link_4" />
        <child link="link_5" />
        <axis xyz="0 1 0" />
        <limit effort="1230" lower="-2.1816" upper="2.1816" velocity="2.26893" />
    </joint>
    <link name="link_6">
        <inertial>
            <origin rpy="0 0 0" xyz="0.0058594 -0.00060952 -5.99E-05" />
            <mass value="5.3437" />
            <inertia ixx="0.02913604" ixy="-0.00000822" ixz="-0.00000086" iyy="0.01533002" iyz="0.00000585" izz="0.01518874" />
        </inertial>
        <visual>
            <origin rpy="0 0 0" xyz="0 0 0" />
            <geometry>
                <mesh filename="package://nj_220_2_7_gazebo/meshes/link_6.STL" />
            </geometry>
            <material name="">
                <color rgba="0.25098 0.25098 0.25098 1" />
            </material>
        </visual>
        <collision>
            <origin rpy="0 0 0" xyz="0 0 0" />
            <geometry>
                <mesh filename="package://nj_220_2_7_gazebo/meshes/link_6.STL" />
            </geometry>
        </collision>
    </link>
    <joint name="joint_6" type="revolute">
        <origin rpy="0 0 0" xyz="0.2085 0 0" />
        <parent link="link_5" />
        <child link="link_6" />
        <axis xyz="1 0 0" />
        <limit effort="712" lower="-6.2831853" upper="6.2831853" velocity="3.40339" />
    </joint>
    <link name="link_3_virtual" />
    <joint name="joint_2m" type="revolute">
        <origin rpy="0 0 0" xyz="0 0 1.175" />
        <parent link="link_2" />
        <child link="link_3_virtual" />
        <axis xyz="0 1 0" />
        <mimic joint="joint_2" multiplier="-1" offset="0" />
        <limit effort="100000" lower="-6.2831853" upper="6.2831853" velocity="3.40339" />
    </joint>
    <link name="link_2_1">
        <inertial>
            <origin rpy="0 0 0" xyz="0.14943 -0.0063786 0.023924" />
            <mass value="41.905" />
            <inertia ixx="0.18520588" ixy="-0.07064049" ixz="0.17218606" iyy="1.70899486" iyz="-0.00657138" izz="1.77577899" />
        </inertial>
        <visual>
            <origin rpy="0 0 0" xyz="0 0 0" />
            <geometry>
                <mesh filename="package://nj_220_2_7_gazebo/meshes/link_2_1.STL" />
            </geometry>
            <material name="">
                <color rgba="1 0 0 1" />
            </material>
        </visual>
        <collision>
            <origin rpy="0 0 0" xyz="0 0 0" />
            <geometry>
                <mesh filename="package://nj_220_2_7_gazebo/meshes/link_2_1.STL" />
            </geometry>
        </collision>
    </link>
    <joint name="joint_2_1" type="revolute">
        <origin rpy="1.570796327 0.087266 3.141592654" xyz="0.400 -0.1945 0.499" />
        <parent link="link_1" />
        <child link="link_2_1" />
        <axis xyz="0 0 1" />
        <limit effort="0" lower="-6.2831853" upper="6.2831853" velocity="0" />
        <mimic joint="joint_3" multiplier="-1" offset="0" />
    </joint>
    <link name="link_2_2_virtual" />
    <joint name="joint_2_2" type="continuous">
        <origin rpy="0 0 0.087266" xyz="0.350 0 0.015" />
        <parent link="link_2_1" />
        <child link="link_2_2_virtual" />
        <axis xyz="0 0 1" />
        <mimic joint="joint_3" multiplier="1" offset="0" />
    </joint>
    <link name="link_2_2">
        <inertial>
            <origin rpy="0 0 0" xyz="0.06443 0.51885 0.01485" />
            <mass value="60.72" />
            <inertia ixx="21.93937071" ixy="1.89190480" ixz="0.05733724" iyy="0.41028863" iyz="0.47064670" izz="22.27041146" />
        </inertial>
        <visual>
            <origin rpy="0 0 0" xyz="0 0 0" />
            <geometry>
                <mesh filename="package://nj_220_2_7_gazebo/meshes/link_2_2.STL" />
            </geometry>
        </visual>
        <collision>
            <origin rpy="0 0 0" xyz="0 0 0" />
            <geometry>
                <mesh filename="package://nj_220_2_7_gazebo/meshes/link_2_2.STL" />
            </geometry>
        </collision>
    </link>
    <joint name="joint_2_3" type="continuous">
        <origin rpy="0 0 0" xyz="0.0 0.0 0.0" />
        <parent link="link_2_2_virtual" />
        <child link="link_2_2" />
        <axis xyz="0 0 1" />
        <mimic joint="joint_2" multiplier="1" offset="0" />
    </joint>
    <link name="flange">
        <inertial>
            <origin rpy="0 0 0" xyz="0 0 0" />
            <mass value="0.01" />
            <inertia ixx="0.00001" ixy="0.00000" ixz="0.00000" iyy="0.00001" iyz="0.00000" izz="0.00000" />
        </inertial>
    </link>
    <joint name="link_6_to_flange" type="fixed">
        <origin rpy="0 0 0" xyz="0 0 -0.0395" />
        <parent link="link_6" />
        <child link="flange" />
        <axis xyz="0 0 0" />
    </joint>
    <!-- Stroke Ends -->
    <link name="external_piece">
        <inertial>
            <origin rpy="0 0 0" xyz="0.25149 0 0.08305" />
            <mass value="11.17" />
            <inertia ixx="0.12505051" ixy="0" ixz="0.20615167" iyy="0.86139689" iyz="0" izz="0.75193919" />
        </inertial>
        <visual>
            <origin rpy="0 0 0" xyz="0 0 0" />
            <geometry>
                <mesh filename="package://nj_220_2_7_gazebo/meshes/external_part.STL" />
            </geometry>
        </visual>
        <collision>
            <origin rpy="0 0 0" xyz="0 0 0" />
            <geometry>
                <mesh filename="package://nj_220_2_7_gazebo/meshes/external_part.STL" />
            </geometry>
        </collision>
    </link>
    <joint name="joint_external_piece" type="fixed">
        <origin rpy="0 0 0" xyz="0 0 0" />
        <parent link="link_1" />
        <child link="external_piece" />
        <axis xyz="0 0 0" />
    </joint>
    <link name="motor_1">
        <inertial>
            <origin rpy="0 0 0" xyz="0 0.00059 -0.13134" />
            <mass value="74.18" />
            <inertia ixx="2.03862179" ixy="0.00000294" ixz="0.00001194" iyy="2.03393681" iyz="-0.01109897" izz="0.37378121" />
        </inertial>
        <visual>
            <origin rpy="0 0 0" xyz="0 0 0" />
            <geometry>
                <mesh filename="package://nj_220_2_7_gazebo/meshes/motor_80.STL" />
            </geometry>
        </visual>
        <collision>
            <origin rpy="0 0 0" xyz="0 0 0" />
            <geometry>
                <mesh filename="package://nj_220_2_7_gazebo/meshes/motor_80.STL" />
            </geometry>
        </collision>
    </link>
    <joint name="joint_motor_1" type="fixed">
        <origin rpy="0 0 4.194026193" xyz="-0.1567 0.0905 0.12075" />
        <parent link="link_1" />
        <child link="motor_1" />
        <axis xyz="0 0 0" />
    </joint>
    <link name="motor_2">
        <inertial>
            <origin rpy="0 0 0" xyz="0 0.00055 -0.14385" />
            <mass value="80.26" />
            <inertia ixx="2.5764983" ixy="0.00000380" ixz="0.01312758" iyy="2.49873445" iyz="-0.0000105" izz="0.40399789" />
        </inertial>
        <visual>
            <origin rpy="0 0 0" xyz="0 0 0" />
            <geometry>
                <mesh filename="package://nj_220_2_7_gazebo/meshes/motor_90.STL" />
            </geometry>
        </visual>
        <collision>
            <origin rpy="0 0 0" xyz="0 0 0" />
            <geometry>
                <mesh filename="package://nj_220_2_7_gazebo/meshes/motor_90.STL" />
            </geometry>
        </collision>
    </link>
    <joint name="joint_motor_2" type="fixed">
        <origin rpy="-1.570796327 1.570796327 0" xyz="0.400 0.2955 0.499" />
        <parent link="link_1" />
        <child link="motor_2" />
        <axis xyz="0 0 0" />
    </joint>
    <link name="motor_3">
        <inertial>
            <origin rpy="0 0 0" xyz="0 0.00059 -0.13134" />
            <mass value="74.18" />
            <inertia ixx="2.03862179" ixy="0.00000294" ixz="0.00001194" iyy="2.03393681" iyz="-0.01109897" izz="0.37378121" />
        </inertial>
        <visual>
            <origin rpy="0 0 0" xyz="0 0 0" />
            <geometry>
                <mesh filename="package://nj_220_2_7_gazebo/meshes/motor_80.STL" />
            </geometry>
        </visual>
        <collision>
            <origin rpy="0 0 0" xyz="0 0 0" />
            <geometry>
                <mesh filename="package://nj_220_2_7_gazebo/meshes/motor_80.STL" />
            </geometry>
        </collision>
    </link>
    <joint name="joint_motor_3" type="fixed">
        <origin rpy="1.570796327 1.570796327 0" xyz="0.400 -0.358 0.499" />
        <parent link="link_1" />
        <child link="motor_3" />
        <axis xyz="0 0 0" />
    </joint>
    <link name="motor_4">
        <inertial>
            <origin rpy="0 0 0" xyz="0.00125 0 -0.0852" />
            <mass value="28" />
            <inertia ixx="0.33783188" ixy="-0.00000254" ixz="-0.00532880" iyy="0.34073438" iyz="0.00000366" izz="0.08086422" />
        </inertial>
        <visual>
            <origin rpy="0 0 0" xyz="0 0 0" />
            <geometry>
                <mesh filename="package://nj_220_2_7_gazebo/meshes/motor_50.STL" />
            </geometry>
        </visual>
        <collision>
            <origin rpy="0 0 0" xyz="0 0 0" />
            <geometry>
                <mesh filename="package://nj_220_2_7_gazebo/meshes/motor_50.STL" />
            </geometry>
        </collision>
    </link>
    <joint name="joint_motor_4" type="fixed">
        <origin rpy="3.141592654 1.570796327 0" xyz="-0.200 0.21052 0.175" />
        <parent link="link_3" />
        <child link="motor_4" />
        <axis xyz="0 -1 0" />
    </joint>
    <link name="motor_5">
        <inertial>
            <origin rpy="0 0 0" xyz="0.00125 0 -0.0852" />
            <mass value="28" />
            <inertia ixx="0.33783188" ixy="-0.00000254" ixz="-0.00532880" iyy="0.34073438" iyz="0.00000366" izz="0.08086422" />
        </inertial>
        <visual>
            <origin rpy="0 0 0" xyz="0 0 0" />
            <geometry>
                <mesh filename="package://nj_220_2_7_gazebo/meshes/motor_50.STL" />
            </geometry>
        </visual>
        <collision>
            <origin rpy="0 0 0" xyz="0 0 0" />
            <geometry>
                <mesh filename="package://nj_220_2_7_gazebo/meshes/motor_50.STL" />
            </geometry>
        </collision>
    </link>
    <joint name="joint_motor_5" type="fixed">
        <origin rpy="1.570796327 0 -1.570796327" xyz="-0.1675 0 0.250" />
        <parent link="link_3" />
        <child link="motor_5" />
        <axis xyz="0 -1 0" />
    </joint>
    <link name="motor_6">
        <inertial>
            <origin rpy="0 0 0" xyz="0.00125 0 -0.0852" />
            <mass value="28" />
            <inertia ixx="0.33783188" ixy="-0.00000254" ixz="-0.00532880" iyy="0.34073438" iyz="0.00000366" izz="0.08086422" />
        </inertial>
        <visual>
            <origin rpy="0 0 0" xyz="0 0 0" />
            <geometry>
                <mesh filename="package://nj_220_2_7_gazebo/meshes/motor_50.STL" />
            </geometry>
        </visual>
        <collision>
            <origin rpy="0 0 0" xyz="0 0 0" />
            <geometry>
                <mesh filename="package://nj_220_2_7_gazebo/meshes/motor_50.STL" />
            </geometry>
        </collision>
    </link>
    <joint name="joint_motor_6" type="fixed">
        <origin rpy="-1.570796327 0 1.570796327" xyz="-0.1675 0.155 0.34577" />
        <parent link="link_3" />
        <child link="motor_6" />
        <axis xyz="0 -1 0" />
    </joint>
    <!-- End Stroke End -->
    <transmission name="tran_1">
        <type>transmission_interface/SimpleTransmission</type>
        <joint name="joint_1">
            <hardwareInterface>hardware_interface/PositionJointInterface</hardwareInterface>
        </joint>
        <actuator name="motor_1">
            <mechanicalReduction>1</mechanicalReduction>
            <hardwareInterface>hardware_interface/EffortJointInterface</hardwareInterface>
        </actuator>
    </transmission>
    <transmission name="tran_2">
        <type>transmission_interface/SimpleTransmission</type>
        <joint name="joint_2">
            <hardwareInterface>hardware_interface/PositionJointInterface</hardwareInterface>
        </joint>
        <actuator name="motor_2">
            <mechanicalReduction>1</mechanicalReduction>
            <hardwareInterface>hardware_interface/EffortJointInterface</hardwareInterface>
        </actuator>
    </transmission>
    <transmission name="tran_3">
        <type>transmission_interface/SimpleTransmission</type>
        <joint name="joint_3">
            <hardwareInterface>hardware_interface/PositionJointInterface</hardwareInterface>
        </joint>
        <actuator name="motor_3">
            <mechanicalReduction>1</mechanicalReduction>
            <hardwareInterface>hardware_interface/EffortJointInterface</hardwareInterface>
        </actuator>
    </transmission>
    <transmission name="tran_4">
        <type>transmission_interface/SimpleTransmission</type>
        <joint name="joint_4">
            <hardwareInterface>hardware_interface/PositionJointInterface</hardwareInterface>
        </joint>
        <actuator name="motor_4">
            <mechanicalReduction>1</mechanicalReduction>
            <hardwareInterface>hardware_interface/EffortJointInterface</hardwareInterface>
        </actuator>
    </transmission>
    <transmission name="tran_5">
        <type>transmission_interface/SimpleTransmission</type>
        <joint name="joint_5">
            <hardwareInterface>hardware_interface/PositionJointInterface</hardwareInterface>
        </joint>
        <actuator name="motor_5">
            <mechanicalReduction>1</mechanicalReduction>
            <hardwareInterface>hardware_interface/EffortJointInterface</hardwareInterface>
        </actuator>
    </transmission>
    <transmission name="tran_6">
        <type>transmission_interface/SimpleTransmission</type>
        <joint name="joint_6">
            <hardwareInterface>hardware_interface/PositionJointInterface</hardwareInterface>
        </joint>
        <actuator name="motor_6">
            <mechanicalReduction>1</mechanicalReduction>
            <hardwareInterface>hardware_interface/EffortJointInterface</hardwareInterface>
        </actuator>
    </transmission>
    <joint name="world_to_base_link" type="fixed">
        <origin rpy="0 0 0" xyz="0 0 0" />
        <parent link="world" />
        <child link="base_link" />
    </joint>
    <transmission name="trans_joint_2m">
        <type>transmission_interface/SimpleTransmission</type>
        <joint name="joint_2m">
            <hardwareInterface>hardware_interface/EffortJointInterface</hardwareInterface>
        </joint>
        <actuator name="joint_2m_motor">
            <hardwareInterface>hardware_interface/EffortJointInterface</hardwareInterface>
            <mechanicalReduction>1</mechanicalReduction>
        </actuator>
    </transmission>
    <transmission name="trans_joint_2_1">
        <type>transmission_interface/SimpleTransmission</type>
        <joint name="joint_2_1">
            <hardwareInterface>hardware_interface/EffortJointInterface</hardwareInterface>
        </joint>
        <actuator name="joint_2_1_motor">
            <hardwareInterface>hardware_interface/EffortJointInterface</hardwareInterface>
            <mechanicalReduction>1</mechanicalReduction>
        </actuator>
    </transmission>
    <transmission name="trans_joint_2_2">
        <type>transmission_interface/SimpleTransmission</type>
        <joint name="joint_2_2">
            <hardwareInterface>hardware_interface/EffortJointInterface</hardwareInterface>
        </joint>
        <actuator name="joint_2_2_motor">
            <hardwareInterface>hardware_interface/EffortJointInterface</hardwareInterface>
            <mechanicalReduction>1</mechanicalReduction>
        </actuator>
    </transmission>
    <transmission name="trans_joint_2_3">
        <type>transmission_interface/SimpleTransmission</type>
        <joint name="joint_2_3">
            <hardwareInterface>hardware_interface/EffortJointInterface</hardwareInterface>
        </joint>
        <actuator name="joint_2_3_motor">
            <hardwareInterface>hardware_interface/EffortJointInterface</hardwareInterface>
            <mechanicalReduction>1</mechanicalReduction>
        </actuator>
    </transmission>
    <gazebo>
        <plugin name="gazebo_ros_control">
            <robotNamespace>/</robotNamespace>
        </plugin>
    </gazebo>
</robot>

