<?xml version="1.0" ?>
<robot xmlns:xacro="http://ros.org/wiki/xacro">
<!-- <xacro:macro name="nj_220_2_7" params="prefix:='' interface:=hardware_interface/EffortJointInterface"> -->
<xacro:macro name="nj_220_2_7" params="prefix:='' interface:=hardware_interface/PositionJointInterface">

  <selfCollide>0</selfCollide>
  <gazebo>
    <selfCollide>0</selfCollide>
  </gazebo>

  <xacro:property name="joint_1_vel_limit" value="1.74533" />    <!--  100°/s -->
  <xacro:property name="joint_2_vel_limit" value="1.5708"  />    <!--  90°/s -->
  <xacro:property name="joint_3_vel_limit" value="1.91986" />    <!--  110°/s -->
  <xacro:property name="joint_4_vel_limit" value="2.26893" />    <!--  130°/s -->
  <xacro:property name="joint_5_vel_limit" value="2.26893" />    <!--  130°/s -->
  <xacro:property name="joint_6_vel_limit" value="3.40339" />    <!--  195°/s -->

  <xacro:property name="joint_1_eff_limit" value="100000" />
  <xacro:property name="joint_2_eff_limit" value="100000" />
  <xacro:property name="joint_3_eff_limit" value="100000" />
  <xacro:property name="joint_4_eff_limit" value="1230" />
  <xacro:property name="joint_5_eff_limit" value="1230" />
  <xacro:property name="joint_6_eff_limit" value="712" />

  <link name="${prefix}base_link">
    <inertial>
      <origin
        xyz="0.035817 -0.00001 0.13320"
        rpy="0 0 0" />
      <mass
        value="780.97" />
      <inertia
        ixx="39.64573032"
        ixy="0.00269524"
        ixz="-3.73357627"
        iyy="48.50586929"
        iyz="-0.00127807"
        izz="49.079656" />
    </inertial>
    <visual>
      <origin
        xyz="0 0 0"
        rpy="0 0 0" />
      <geometry>
        <mesh
          filename="package://nj_220_2_7_gazebo/meshes/base_link.STL" />
      </geometry>
      <material
        name="">
        <color
          rgba="1 0 0 1" />
      </material>
    </visual>
    <collision>
      <origin
        xyz="0 0 0"
        rpy="0 0 0" />
      <geometry>
        <mesh
          filename="package://nj_220_2_7_gazebo/meshes/base_link.STL" />
      </geometry>
    </collision>
  </link>
  <link name="${prefix}link_1">
    <inertial>
      <origin
        xyz="0.31397 0.02536 0.37802"
        rpy="0 0 0" />
      <mass
        value="120.57" />
      <inertia
        ixx="96.14944607"
        ixy="2.82831578"
        ixz="59.92048931"
        iyy="132.52767347"
        iyz="3.87136939"
        izz="76.40305744" />
    </inertial>
    <visual>
      <origin
        xyz="0 0 0"
        rpy="0 0 0" />
      <geometry>
        <mesh
          filename="package://nj_220_2_7_gazebo/meshes/link_1.STL" />
      </geometry>
      <material
        name="">
        <color
          rgba="1 0 0 1" />
      </material>
    </visual>
    <collision>
      <origin
        xyz="0 0 0"
        rpy="0 0 0" />
      <geometry>
        <mesh
          filename="package://nj_220_2_7_gazebo/meshes/link_1.STL" />
      </geometry>
    </collision>
  </link>
  <joint name="${prefix}joint_1" type="revolute">
    <origin
      xyz="0 0 0.331"
      rpy="0 0 0" />
    <parent
      link="${prefix}base_link" />
    <child
      link="${prefix}link_1" />
    <axis
      xyz="0 0 1" />
    <limit
      lower="-1.570796327"
      upper="1.570796327"
      effort="${joint_1_eff_limit}"
      velocity="${joint_1_vel_limit}" />
  </joint>
  <link name="${prefix}link_2">
    <inertial>
      <origin
        xyz="0.018416 -0.00326 0.51384"
        rpy="0 0 0" />
      <mass
        value="120.34" />
      <inertia
        ixx="53.73638778"
        ixy="-0.00887173"
        ixz="1.24711967"
        iyy="53.48705119"
        iyz="-0.66793611"
        izz="2.25971599" />
    </inertial>
    <visual>
      <origin
        xyz="0 0 0"
        rpy="0 0 0" />
      <geometry>
        <mesh
          filename="package://nj_220_2_7_gazebo/meshes/link_2.STL" />
      </geometry>
      <material
        name="">
        <color
          rgba="1 0 0 1" />
      </material>
    </visual>
    <collision>
      <origin
        xyz="0 0 0"
        rpy="0 0 0" />
      <geometry>
        <mesh
          filename="package://nj_220_2_7_gazebo/meshes/link_2.STL" />
      </geometry>
    </collision>
  </link>
  <joint name="${prefix}joint_2" type="revolute">
    <origin
      xyz="0.4 0 0.499"
      rpy="0 0 0" />
    <parent
      link="${prefix}link_1" />
    <child
      link="${prefix}link_2" />
    <axis
      xyz="0 1 0" />
    <limit
      lower="-1.308996939"
      upper="1.658062789"
      effort="${joint_2_eff_limit}"
      velocity="${joint_2_vel_limit}" />
  </joint>
  <link name="${prefix}link_2_1">
     <inertial>
       <origin
         xyz="0.14943 -0.0063786 0.023924"
         rpy="0 0 0" />
       <mass
         value="41.905" />
       <inertia
         ixx="0.18520588"
         ixy="-0.07064049"
         ixz="0.17218606"
         iyy="1.70899486"
         iyz="-0.00657138"
         izz="1.77577899" />
     </inertial>
     <visual>
       <origin
         xyz="0 0 0"
         rpy="0 0 0" />
       <geometry>
         <mesh
           filename="package://nj_220_2_7_gazebo/meshes/link_2_1.STL" />
       </geometry>
       <material
         name="">
         <color
           rgba="1 0 0 1" />
       </material>
     </visual>
     <collision>
       <origin
         xyz="0 0 0"
         rpy="0 0 0" />
       <geometry>
         <mesh
           filename="package://nj_220_2_7_gazebo/meshes/link_2_1.STL" />
       </geometry>
     </collision>
   </link>
  <joint name="${prefix}joint_3" type="revolute">
     <origin xyz="0.400 -0.1945 0.499" rpy="1.570796327 0.087266 3.141592654" />
     <parent link="${prefix}link_1" />
     <child link="${prefix}link_2_1" />
     <axis xyz="0 0 1" />
     <limit
       lower="-4.468042885"
       upper="0.174532925"
       effort="${joint_3_eff_limit}"
       velocity="${joint_3_vel_limit}" />
  </joint>
  <link name="${prefix}link_2_2">
     <inertial>
       <origin
         xyz="0.06443 0.51885 0.01485"
         rpy="0 0 0" />
       <mass
         value="60.72" />
       <inertia
         ixx="21.93937071"
         ixy="1.89190480"
         ixz="0.05733724"
         iyy="0.41028863"
         iyz="0.47064670"
         izz="22.27041146" />
     </inertial>
     <visual>
       <origin
         xyz="0 0 0"
         rpy="0 0 0" />
       <geometry>
         <mesh
           filename="package://nj_220_2_7_gazebo/meshes/link_2_2.STL" />
       </geometry>
     </visual>
     <collision>
       <origin
         xyz="0 0 0"
         rpy="0 0 0" />
       <geometry>
         <mesh
           filename="package://nj_220_2_7_gazebo/meshes/link_2_2.STL" />
       </geometry>
     </collision>
  </link>
  <joint name="${prefix}joint_2_1" type="revolute">
    <origin
      xyz="0.350 0 0.015"
      rpy="0 0 0.087266" />
    <parent
      link="${prefix}link_2_1" />
    <child
      link="${prefix}link_2_2" />
    <axis
      xyz="0 0 1" />
    <limit
      lower="-6.2831853"
      upper="6.2831853"
      effort="${joint_6_eff_limit}"
      velocity="${joint_6_vel_limit}" />
  </joint>
  <link name="${prefix}link_2_3">
    <inertial>
      <origin xyz="0 0 0" rpy="0 0 0" />
      <mass value="0.01" />
      <inertia
        ixx="0.00001"
        ixy="0.00000"
        ixz="0.00000"
        iyy="0.00001"
        iyz="0.00000"
        izz="0.00000" />
    </inertial>
  </link>
  <joint name="${prefix}joint_2_2" type="revolute">
    <origin xyz="0.0 1.175 0.0" rpy="0 0 -0.087266" />
    <parent link="${prefix}link_2_2" />
    <child link="${prefix}link_2_3" />
    <axis xyz="0 0 1" />
    <limit
      lower="-6.2831853"
      upper="6.2831853"
      effort="${joint_6_eff_limit}"
      velocity="${joint_6_vel_limit}" />
  </joint>
  <link name="${prefix}link_3">
    <inertial>
      <origin
        xyz="-0.04239 0.01939 0.2104"
        rpy="0 0 0" />
      <mass
        value="303.81" />
      <inertia
        ixx="24.45402173"
        ixy="-0.58037596"
        ixz="-2.46563321"
        iyy="20.71802091"
        iyz="2.40454026"
        izz="9.01610712" />
    </inertial>
    <visual>
      <origin
        xyz="0 0 0"
        rpy="0 0 0" />
      <geometry>
        <mesh
          filename="package://nj_220_2_7_gazebo/meshes/link_3.STL" />
      </geometry>
      <material
        name="">
        <color
          rgba="1 0 0 1" />
      </material>
    </visual>
    <collision>
      <origin
        xyz="0 0 0"
        rpy="0 0 0" />
      <geometry>
        <mesh
          filename="package://nj_220_2_7_gazebo/meshes/link_3.STL" />
      </geometry>
    </collision>
  </link>


  <link name="${prefix}link_4">
    <inertial>
      <origin
        xyz="0.71228 -0.02567 -0.00003"
        rpy="0 0 0" />
      <mass
        value="90.963" />
      <inertia
        ixx="0.68929228290"
        ixy="-2.39235486446"
        ixz="-0.00192589885"
        iyy="58.11987131958"
        iyz="-0.00017654018"
        izz="58.29818388998" />
    </inertial>
    <visual>
      <origin
        xyz="0 0 0"
        rpy="0 0 0" />
      <geometry>
        <mesh
          filename="package://nj_220_2_7_gazebo/meshes/link_4.STL" />
      </geometry>
      <material
        name="">
        <color
          rgba="1 0 0 1" />
      </material>
    </visual>
    <collision>
      <origin
        xyz="0 0 0"
        rpy="0 0 0" />
      <geometry>
        <mesh
          filename="package://nj_220_2_7_gazebo/meshes/link_4.STL" />
      </geometry>
    </collision>
  </link>
  <joint name="${prefix}joint_4" type="revolute">
    <origin
      xyz="0.105 0 0.25"
      rpy="0 0 0" />
    <parent
      link="${prefix}link_3" />
    <child
      link="${prefix}link_4" />
    <axis
      xyz="1 0 0" />
    <limit
      lower="-6.2831853"
      upper="6.2831853"
      effort="${joint_4_eff_limit}"
      velocity="${joint_4_vel_limit}" />
  </joint>
  <link name="${prefix}link_5">
    <inertial>
      <origin
        xyz="0.09375 0.01506 0.00002"
        rpy="0 0 0" />
      <mass
        value="50.615" />
      <inertia
        ixx="0.67974396"
        ixy="0.04508972"
        ixz="0.00009980"
        iyy="0.83229961"
        iyz="0.00011851"
        izz="1.32231171" />
    </inertial>
    <visual>
      <origin
        xyz="0 0 0"
        rpy="0 0 0" />
      <geometry>
        <mesh
          filename="package://nj_220_2_7_gazebo/meshes/link_5.STL" />
      </geometry>
      <material
        name="">
        <color
          rgba="1 0 0 1" />
      </material>
    </visual>
    <collision>
      <origin
        xyz="0 0 0"
        rpy="0 0 0" />
      <geometry>
        <mesh
          filename="package://nj_220_2_7_gazebo/meshes/link_5.STL" />
      </geometry>
    </collision>
  </link>
  <joint name="${prefix}joint_5" type="revolute">
    <origin
      xyz="1.02033 0 0"
      rpy="0 0 0" />
    <parent
      link="${prefix}link_4" />
    <child
      link="${prefix}link_5" />
    <axis
      xyz="0 1 0" />
    <limit
      lower="-2.1816"
      upper="2.1816"
      effort="${joint_5_eff_limit}"
      velocity="${joint_5_vel_limit}" />
  </joint>
  <link name="${prefix}link_6">
    <inertial>
      <origin
        xyz="0.0058594 -0.00060952 -5.99E-05"
        rpy="0 0 0" />
      <mass
        value="5.3437" />
      <inertia
        ixx="0.02913604"
        ixy="-0.00000822"
        ixz="-0.00000086"
        iyy="0.01533002"
        iyz="0.00000585"
        izz="0.01518874" />
    </inertial>
    <visual>
      <origin
        xyz="0 0 0"
        rpy="0 0 0" />
      <geometry>
        <mesh
          filename="package://nj_220_2_7_gazebo/meshes/link_6.STL" />
      </geometry>
      <material
        name="">
        <color
          rgba="0.25098 0.25098 0.25098 1" />
      </material>
    </visual>
    <collision>
      <origin
        xyz="0 0 0"
        rpy="0 0 0" />
      <geometry>
        <mesh
          filename="package://nj_220_2_7_gazebo/meshes/link_6.STL" />
      </geometry>
    </collision>
  </link>
  <joint name="${prefix}joint_6" type="revolute">
    <origin
      xyz="0.2085 0 0"
      rpy="0 0 0" />
    <parent
      link="${prefix}link_5" />
    <child
      link="${prefix}link_6" />
    <axis
      xyz="1 0 0" />
    <limit
      lower="-6.2831853"
      upper="6.2831853"
      effort="${joint_6_eff_limit}"
      velocity="${joint_6_vel_limit}" />
  </joint>

  <joint name="${prefix}closing_joint" type="revolute">
    <origin
      xyz="0 0 1.175"
      rpy="0 0 0" />
    <parent
      link="${prefix}link_2" />
    <child
      link="${prefix}link_3" />
    <axis
      xyz="0 1 0" />
    <limit
      lower="-6.2831853"
      upper="6.2831853"
      effort="${joint_6_eff_limit}"
      velocity="${joint_6_vel_limit}" />
  </joint>

  <gazebo>
    <joint name="${prefix}joint_3_1" type="fixed">
      <parent>${prefix}link_2_3</parent>
      <child>${prefix}link_3</child>
      <pose relative_to="${prefix}link_2"> -0.350, 0, 0.179, 1.571, 0, -3.054326654</pose>
      <axis>
        <xyz>0 0 1</xyz>
      </axis>
    </joint>
  </gazebo>

  <!-- <joint name="${prefix}joint_3_1" type="fixed">
    <origin
      xyz="-0.350 0 0.179"
      rpy="1.571 0.000 -3.054326654" />
    <parent
      link="${prefix}link_2_3" />
    <child
      link="${prefix}link_3" />
    <axis
      xyz="0 0 1" />
    <limit
      lower="-6.2831853"
      upper="6.2831853"
      effort="${joint_6_eff_limit}"
      velocity="${joint_6_vel_limit}" />
  </joint> -->

  <!-- <gazebo>
    <joint name="${prefix}closing_joint" type="revolute">
      <parent>${prefix}link_2</parent>
      <child>${prefix}link_3</child>
      <pose relative_to="${prefix}link_2"> 0, 0, 1.175, 0, 0, 0</pose>
      <axis>
        <xyz>0 1 0</xyz>
      </axis>
    </joint>
  </gazebo> -->

  <link name="${prefix}flange">
    <inertial>
      <origin xyz="0 0 0" rpy="0 0 0" />
      <mass value="0.01" />
      <inertia
        ixx="0.00001"
        ixy="0.00000"
        ixz="0.00000"
        iyy="0.00001"
        iyz="0.00000"
        izz="0.00000" />
    </inertial>
  </link>
  <joint name="${prefix}link_6_to_flange" type="fixed">
    <origin xyz="0 0 -0.0395" rpy="0 0 0" />
    <parent link="${prefix}link_6" />
    <child link="${prefix}flange" />
    <axis xyz="0 0 0" />
  </joint>

  <!-- Stroke Ends -->
  <link name="${prefix}external_piece">
    <inertial>
      <origin
        xyz="0.25149 0 0.08305"
        rpy="0 0 0" />
      <mass
        value="11.17" />
      <inertia
        ixx="0.12505051"
        ixy="0"
        ixz="0.20615167"
        iyy="0.86139689"
        iyz="0"
        izz="0.75193919" />
    </inertial>
    <visual>
      <origin
        xyz="0 0 0"
        rpy="0 0 0" />
      <geometry>
        <mesh
          filename="package://nj_220_2_7_gazebo/meshes/external_part.STL" />
      </geometry>
    </visual>
    <collision>
      <origin
        xyz="0 0 0"
        rpy="0 0 0" />
      <geometry>
        <mesh
          filename="package://nj_220_2_7_gazebo/meshes/external_part.STL" />
      </geometry>
    </collision>
  </link>
  <joint name="${prefix}joint_external_piece" type="fixed">
    <origin
      xyz="0 0 0"
      rpy="0 0 0" />
    <parent
      link="${prefix}link_1" />
    <child
      link="${prefix}external_piece" />
    <axis xyz="0 0 0" />
  </joint>
  <link name="${prefix}motor_1">
    <inertial>
      <origin
        xyz="0 0.00059 -0.13134"
        rpy="0 0 0" />
      <mass
        value="74.18" />
      <inertia
        ixx="2.03862179"
        ixy="0.00000294"
        ixz="0.00001194"
        iyy="2.03393681"
        iyz="-0.01109897"
        izz="0.37378121" />
    </inertial>
    <visual>
      <origin
        xyz="0 0 0"
        rpy="0 0 0" />
      <geometry>
        <mesh
          filename="package://nj_220_2_7_gazebo/meshes/motor_80.STL" />
      </geometry>
    </visual>
    <collision>
      <origin
        xyz="0 0 0"
        rpy="0 0 0" />
      <geometry>
        <mesh
          filename="package://nj_220_2_7_gazebo/meshes/motor_80.STL" />
      </geometry>
    </collision>
  </link>
  <joint name="${prefix}joint_motor_1" type="fixed">
    <origin
      xyz="-0.1567 0.0905 0.12075"
      rpy="0 0 4.194026193" />
    <parent
      link="${prefix}link_1" />
    <child
      link="${prefix}motor_1" />
    <axis xyz="0 0 0" />
  </joint>
  <link name="${prefix}motor_2">
    <inertial>
      <origin
        xyz="0 0.00055 -0.14385"
        rpy="0 0 0" />
      <mass
        value="80.26" />
      <inertia
        ixx="2.5764983"
        ixy="0.00000380"
        ixz="0.01312758"
        iyy="2.49873445"
        iyz="-0.0000105"
        izz="0.40399789" />
    </inertial>
    <visual>
      <origin
        xyz="0 0 0"
        rpy="0 0 0" />
      <geometry>
        <mesh
          filename="package://nj_220_2_7_gazebo/meshes/motor_90.STL" />
      </geometry>
    </visual>
    <collision>
      <origin
        xyz="0 0 0"
        rpy="0 0 0" />
      <geometry>
        <mesh
          filename="package://nj_220_2_7_gazebo/meshes/motor_90.STL" />
      </geometry>
    </collision>
  </link>
  <joint name="${prefix}joint_motor_2" type="fixed">
    <origin
      xyz="0.400 0.2955 0.499"
      rpy="-1.570796327 1.570796327 0" />
    <parent
      link="${prefix}link_1" />
    <child
      link="${prefix}motor_2" />
      <axis xyz="0 0 0" />
  </joint>
  <link name="${prefix}motor_3">
    <inertial>
      <origin
        xyz="0 0.00059 -0.13134"
        rpy="0 0 0" />
      <mass
        value="74.18" />
      <inertia
        ixx="2.03862179"
        ixy="0.00000294"
        ixz="0.00001194"
        iyy="2.03393681"
        iyz="-0.01109897"
        izz="0.37378121" />
    </inertial>
    <visual>
      <origin
        xyz="0 0 0"
        rpy="0 0 0" />
      <geometry>
        <mesh
          filename="package://nj_220_2_7_gazebo/meshes/motor_80.STL" />
      </geometry>
    </visual>
    <collision>
      <origin
        xyz="0 0 0"
        rpy="0 0 0" />
      <geometry>
        <mesh
          filename="package://nj_220_2_7_gazebo/meshes/motor_80.STL" />
      </geometry>
    </collision>
  </link>
  <joint name="${prefix}joint_motor_3" type="fixed">
    <origin
      xyz="0.400 -0.358 0.499"
      rpy="1.570796327 1.570796327 0" />
    <parent
      link="${prefix}link_1" />
    <child
      link="${prefix}motor_3" />
      <axis xyz="0 0 0" />
  </joint>
  <link name="${prefix}motor_4">
    <inertial>
      <origin
        xyz="0.00125 0 -0.0852"
        rpy="0 0 0" />
      <mass
        value="28" />
      <inertia
        ixx="0.33783188"
        ixy="-0.00000254"
        ixz="-0.00532880"
        iyy="0.34073438"
        iyz="0.00000366"
        izz="0.08086422" />
    </inertial>
    <visual>
      <origin
        xyz="0 0 0"
        rpy="0 0 0" />
      <geometry>
        <mesh
          filename="package://nj_220_2_7_gazebo/meshes/motor_50.STL" />
      </geometry>
    </visual>
    <collision>
      <origin
        xyz="0 0 0"
        rpy="0 0 0" />
      <geometry>
        <mesh
          filename="package://nj_220_2_7_gazebo/meshes/motor_50.STL" />
      </geometry>
    </collision>
  </link>
  <joint name="${prefix}joint_motor_4"
    type="fixed">
    <origin
      xyz="-0.200 0.21052 0.175"
      rpy="3.141592654 1.570796327 0" />
    <parent
      link="${prefix}link_3" />
    <child
      link="${prefix}motor_4" />
    <axis
      xyz="0 -1 0" />
  </joint>
  <link name="${prefix}motor_5">
    <inertial>
      <origin
        xyz="0.00125 0 -0.0852"
        rpy="0 0 0" />
      <mass
        value="28" />
      <inertia
        ixx="0.33783188"
        ixy="-0.00000254"
        ixz="-0.00532880"
        iyy="0.34073438"
        iyz="0.00000366"
        izz="0.08086422" />
    </inertial>
    <visual>
      <origin
        xyz="0 0 0"
        rpy="0 0 0" />
      <geometry>
        <mesh
          filename="package://nj_220_2_7_gazebo/meshes/motor_50.STL" />
      </geometry>
    </visual>
    <collision>
      <origin
        xyz="0 0 0"
        rpy="0 0 0" />
      <geometry>
        <mesh
          filename="package://nj_220_2_7_gazebo/meshes/motor_50.STL" />
      </geometry>
    </collision>
  </link>
  <joint name="${prefix}joint_motor_5"
    type="fixed">
    <origin
      xyz="-0.1675 0 0.250"
      rpy="1.570796327 0 -1.570796327" />
    <parent
      link="${prefix}link_3" />
    <child
      link="${prefix}motor_5" />
    <axis
      xyz="0 -1 0" />
  </joint>
  <link name="${prefix}motor_6">
    <inertial>
      <origin
        xyz="0.00125 0 -0.0852"
        rpy="0 0 0" />
      <mass
        value="28" />
      <inertia
        ixx="0.33783188"
        ixy="-0.00000254"
        ixz="-0.00532880"
        iyy="0.34073438"
        iyz="0.00000366"
        izz="0.08086422" />
    </inertial>
    <visual>
      <origin
        xyz="0 0 0"
        rpy="0 0 0" />
      <geometry>
        <mesh
          filename="package://nj_220_2_7_gazebo/meshes/motor_50.STL" />
      </geometry>
    </visual>
    <collision>
      <origin
        xyz="0 0 0"
        rpy="0 0 0" />
      <geometry>
        <mesh
          filename="package://nj_220_2_7_gazebo/meshes/motor_50.STL" />
      </geometry>
    </collision>
  </link>
  <joint name="${prefix}joint_motor_6"
    type="fixed">
    <origin
      xyz="-0.1675 0.155 0.34577"
      rpy="-1.570796327 0 1.570796327" />
    <parent
      link="${prefix}link_3" />
    <child
      link="${prefix}motor_6" />
    <axis
      xyz="0 -1 0" />
  </joint>
  <!-- End Stroke End -->

<xacro:include filename="$(find nj_220_2_7_gazebo)/urdf/nj_220_2_7_transmission.xacro" />
<xacro:nj_220_2_7_transmission prefix="${prefix}" interface="${interface}"/>
<xacro:include filename="$(find nj_220_2_7_gazebo)/urdf/nj_220_2_7_gazebo.xacro" />
<xacro:nj_220_2_7_roscontrol prefix="${prefix}"/>

</xacro:macro>
</robot>
