<sdf version='1.7'>
  <model name='nj_220_2_7'>
    <joint name='world_to_base_link' type='fixed'>
      <pose relative_to='__model__'>0 0 0 0 -0 0</pose>
      <parent>world</parent>
      <child>base_link</child>
    </joint>
    <link name='base_link'>
      <pose relative_to='world_to_base_link'>0 0 0 0 -0 0</pose>
      <inertial>
        <pose>0.035817 -1e-05 0.1332 0 -0 0</pose>
        <mass>780.97</mass>
        <inertia>
          <ixx>39.6457</ixx>
          <ixy>0.00269524</ixy>
          <ixz>-3.73358</ixz>
          <iyy>48.5059</iyy>
          <iyz>-0.00127807</iyz>
          <izz>49.0797</izz>
        </inertia>
      </inertial>
      <collision name='base_link_collision'>
        <pose>0 0 0 0 -0 0</pose>
        <geometry>
          <mesh>
            <scale>1 1 1</scale>
            <uri>model://nj_220_2_7_gazebo/meshes/base_link.STL</uri>
          </mesh>
        </geometry>
        <surface>
          <contact>
            <ode/>
          </contact>
          <friction>
            <ode/>
          </friction>
        </surface>
      </collision>
      <visual name='base_link_visual'>
        <pose>0 0 0 0 -0 0</pose>
        <geometry>
          <mesh>
            <scale>1 1 1</scale>
            <uri>model://nj_220_2_7_gazebo/meshes/base_link.STL</uri>
          </mesh>
        </geometry>
        <material>
          <script>
            <name>Gazebo/DarkGrey</name>
            <uri>file://media/materials/scripts/gazebo.material</uri>
          </script>
        </material>
      </visual>
      <self_collide>0</self_collide>
      <gravity>1</gravity>
    </link>
    <joint name='joint_1' type='revolute'>
      <pose relative_to='base_link'>0 0 0.331 0 -0 0</pose>
      <parent>base_link</parent>
      <child>link_1</child>
      <axis>
        <xyz>0 0 1</xyz>
        <limit>
          <lower>-1.5708</lower>
          <upper>1.5708</upper>
          <effort>100000</effort>
          <velocity>1.74533</velocity>
        </limit>
        <dynamics>
          <spring_reference>0</spring_reference>
          <spring_stiffness>0</spring_stiffness>
        </dynamics>
      </axis>
    </joint>
    <link name='link_1'>
      <pose relative_to='joint_1'>0 0 0 0 -0 0</pose>
      <inertial>
        <pose>0.25212 0.014172 0.34073 0 -0 0</pose>
        <mass>360.36</mass>
        <inertia>
          <ixx>123.042</ixx>
          <ixy>6.08766</ixy>
          <ixz>45.5816</ixz>
          <iyy>166.343</iyy>
          <iyz>6.83534</iyz>
          <izz>104.615</izz>
        </inertia>
      </inertial>
      <collision name='link_1_collision'>
        <pose>0 0 0 0 -0 0</pose>
        <geometry>
          <mesh>
            <scale>1 1 1</scale>
            <uri>model://nj_220_2_7_gazebo/meshes/link_1.STL</uri>
          </mesh>
        </geometry>
        <surface>
          <contact>
            <ode/>
          </contact>
          <friction>
            <ode/>
          </friction>
        </surface>
      </collision>
      <collision name='link_1_fixed_joint_lump__external_piece_collision_1'>
        <pose>0 0 0 0 -0 0</pose>
        <geometry>
          <mesh>
            <scale>1 1 1</scale>
            <uri>model://nj_220_2_7_gazebo/meshes/external_part.STL</uri>
          </mesh>
        </geometry>
      </collision>
      <collision name='link_1_fixed_joint_lump__motor_1_collision_2'>
        <pose>-0.1567 0.0905 0.12075 0 0 -2.08916</pose>
        <geometry>
          <mesh>
            <scale>1 1 1</scale>
            <uri>model://nj_220_2_7_gazebo/meshes/motor_80.STL</uri>
          </mesh>
        </geometry>
      </collision>
      <collision name='link_1_fixed_joint_lump__motor_2_collision_3'>
        <pose>0.4 0.2955 0.499 -1.5708 1.5708 0</pose>
        <geometry>
          <mesh>
            <scale>1 1 1</scale>
            <uri>model://nj_220_2_7_gazebo/meshes/motor_90.STL</uri>
          </mesh>
        </geometry>
      </collision>
      <collision name='link_1_fixed_joint_lump__motor_3_collision_4'>
        <pose>0.4 -0.358 0.499 1.5708 1.5708 0</pose>
        <geometry>
          <mesh>
            <scale>1 1 1</scale>
            <uri>model://nj_220_2_7_gazebo/meshes/motor_80.STL</uri>
          </mesh>
        </geometry>
      </collision>
      <visual name='link_1_visual'>
        <pose>0 0 0 0 -0 0</pose>
        <geometry>
          <mesh>
            <scale>1 1 1</scale>
            <uri>model://nj_220_2_7_gazebo/meshes/link_1.STL</uri>
          </mesh>
        </geometry>
        <material>
          <script>
            <name>Gazebo/Grey</name>
            <uri>file://media/materials/scripts/gazebo.material</uri>
          </script>
        </material>
      </visual>
      <visual name='link_1_fixed_joint_lump__external_piece_visual_1'>
        <pose>0 0 0 0 -0 0</pose>
        <geometry>
          <mesh>
            <scale>1 1 1</scale>
            <uri>model://nj_220_2_7_gazebo/meshes/external_part.STL</uri>
          </mesh>
        </geometry>
      </visual>
      <visual name='link_1_fixed_joint_lump__motor_1_visual_2'>
        <pose>-0.1567 0.0905 0.12075 0 0 -2.08916</pose>
        <geometry>
          <mesh>
            <scale>1 1 1</scale>
            <uri>model://nj_220_2_7_gazebo/meshes/motor_80.STL</uri>
          </mesh>
        </geometry>
      </visual>
      <visual name='link_1_fixed_joint_lump__motor_2_visual_3'>
        <pose>0.4 0.2955 0.499 -1.5708 1.5708 0</pose>
        <geometry>
          <mesh>
            <scale>1 1 1</scale>
            <uri>model://nj_220_2_7_gazebo/meshes/motor_90.STL</uri>
          </mesh>
        </geometry>
      </visual>
      <visual name='link_1_fixed_joint_lump__motor_3_visual_4'>
        <pose>0.4 -0.358 0.499 1.5708 1.5708 0</pose>
        <geometry>
          <mesh>
            <scale>1 1 1</scale>
            <uri>model://nj_220_2_7_gazebo/meshes/motor_80.STL</uri>
          </mesh>
        </geometry>
      </visual>
      <self_collide>0</self_collide>
      <gravity>1</gravity>
    </link>
    <joint name='joint_2' type='revolute'>
      <pose relative_to='link_1'>0.4 0 0.499 0 -0 0</pose>
      <parent>link_1</parent>
      <child>link_2</child>
      <axis>
        <xyz>0 1 0</xyz>
        <limit>
          <lower>-1.309</lower>
          <upper>1.65806</upper>
          <effort>100000</effort>
          <velocity>1.5708</velocity>
        </limit>
        <dynamics>
          <spring_reference>0</spring_reference>
          <spring_stiffness>0</spring_stiffness>
        </dynamics>
      </axis>
    </joint>
    <link name='link_2'>
      <pose relative_to='joint_2'>0 0 0 0 -0 0</pose>
      <inertial>
        <pose>0.018416 -0.00326 0.51384 0 -0 0</pose>
        <mass>120.34</mass>
        <inertia>
          <ixx>53.7364</ixx>
          <ixy>-0.00887173</ixy>
          <ixz>1.24712</ixz>
          <iyy>53.4871</iyy>
          <iyz>-0.667936</iyz>
          <izz>2.25972</izz>
        </inertia>
      </inertial>
      <collision name='link_2_collision'>
        <pose>0 0 0 0 -0 0</pose>
        <geometry>
          <mesh>
            <scale>1 1 1</scale>
            <uri>model://nj_220_2_7_gazebo/meshes/link_2.STL</uri>
          </mesh>
        </geometry>
        <surface>
          <contact>
            <ode/>
          </contact>
          <friction>
            <ode/>
          </friction>
        </surface>
      </collision>
      <visual name='link_2_visual'>
        <pose>0 0 0 0 -0 0</pose>
        <geometry>
          <mesh>
            <scale>1 1 1</scale>
            <uri>model://nj_220_2_7_gazebo/meshes/link_2.STL</uri>
          </mesh>
        </geometry>
        <material>
          <script>
            <name>Gazebo/Grey</name>
            <uri>file://media/materials/scripts/gazebo.material</uri>
          </script>
        </material>
      </visual>
      <self_collide>0</self_collide>
      <gravity>1</gravity>
    </link>
    <joint name='joint_2m' type='revolute'>
      <pose relative_to='link_2'>0 0 1.175 0 -0 0</pose>
      <parent>link_2</parent>
      <child>link_3_virtual</child>
      <axis>
        <xyz>0 1 0</xyz>
        <limit>
          <lower>-6.28319</lower>
          <upper>6.28319</upper>
          <effort>100000</effort>
          <velocity>3.40339</velocity>
        </limit>
        <dynamics>
          <spring_reference>0</spring_reference>
          <spring_stiffness>0</spring_stiffness>
        </dynamics>
      </axis>
    </joint>
    <link name='link_3_virtual'>
      <pose relative_to='joint_2m'>0 0 0 0 -0 0</pose>
      <inertial>
        <pose>0 0 0 0 -0 0</pose>
        <mass>0.01</mass>
        <inertia>
          <ixx>1e-05</ixx>
          <ixy>0</ixy>
          <ixz>0</ixz>
          <iyy>1e-05</iyy>
          <iyz>0</iyz>
          <izz>0</izz>
        </inertia>
      </inertial>
      <self_collide>0</self_collide>
      <gravity>1</gravity>
    </link>
    <joint name='joint_3m' type='revolute'>
      <pose relative_to='link_3_virtual'>0 0 0 0 -0 0</pose>
      <parent>link_3_virtual</parent>
      <child>link_3</child>
      <axis>
        <xyz>0 1 0</xyz>
        <limit>
          <lower>-6.28319</lower>
          <upper>6.28319</upper>
          <effort>0</effort>
          <velocity>0</velocity>
        </limit>
        <dynamics>
          <spring_reference>0</spring_reference>
          <spring_stiffness>0</spring_stiffness>
        </dynamics>
      </axis>
    </joint>
    <link name='link_3'>
      <pose relative_to='joint_3m'>0 0 0 0 -0 0</pose>
      <inertial>
        <pose>-0.053381 0.041581 0.220387 0 -0 0</pose>
        <mass>387.81</mass>
        <inertia>
          <ixx>26.6208</ixx>
          <ixy>-0.157573</ixy>
          <ixz>-2.39231</ixz>
          <iyy>22.4795</iyy>
          <iyz>2.19076</iyz>
          <izz>11.5928</izz>
        </inertia>
      </inertial>
      <collision name='link_3_collision'>
        <pose>0 0 0 0 -0 0</pose>
        <geometry>
          <mesh>
            <scale>1 1 1</scale>
            <uri>model://nj_220_2_7_gazebo/meshes/link_3.STL</uri>
          </mesh>
        </geometry>
        <surface>
          <contact>
            <ode/>
          </contact>
          <friction>
            <ode/>
          </friction>
        </surface>
      </collision>
      <collision name='link_3_fixed_joint_lump__motor_4_collision_1'>
        <pose>-0.2 0.21052 0.175 -3.14159 1.5708 0</pose>
        <geometry>
          <mesh>
            <scale>1 1 1</scale>
            <uri>model://nj_220_2_7_gazebo/meshes/motor_50.STL</uri>
          </mesh>
        </geometry>
      </collision>
      <collision name='link_3_fixed_joint_lump__motor_5_collision_2'>
        <pose>-0.1675 0 0.25 1.5708 0 -1.5708</pose>
        <geometry>
          <mesh>
            <scale>1 1 1</scale>
            <uri>model://nj_220_2_7_gazebo/meshes/motor_50.STL</uri>
          </mesh>
        </geometry>
      </collision>
      <collision name='link_3_fixed_joint_lump__motor_6_collision_3'>
        <pose>-0.1675 0.155 0.34577 -1.5708 0 1.5708</pose>
        <geometry>
          <mesh>
            <scale>1 1 1</scale>
            <uri>model://nj_220_2_7_gazebo/meshes/motor_50.STL</uri>
          </mesh>
        </geometry>
      </collision>
      <visual name='link_3_visual'>
        <pose>0 0 0 0 -0 0</pose>
        <geometry>
          <mesh>
            <scale>1 1 1</scale>
            <uri>model://nj_220_2_7_gazebo/meshes/link_3.STL</uri>
          </mesh>
        </geometry>
        <material>
          <script>
            <name>Gazebo/Grey</name>
            <uri>file://media/materials/scripts/gazebo.material</uri>
          </script>
        </material>
      </visual>
      <visual name='link_3_fixed_joint_lump__motor_4_visual_1'>
        <pose>-0.2 0.21052 0.175 -3.14159 1.5708 0</pose>
        <geometry>
          <mesh>
            <scale>1 1 1</scale>
            <uri>model://nj_220_2_7_gazebo/meshes/motor_50.STL</uri>
          </mesh>
        </geometry>
      </visual>
      <visual name='link_3_fixed_joint_lump__motor_5_visual_2'>
        <pose>-0.1675 0 0.25 1.5708 0 -1.5708</pose>
        <geometry>
          <mesh>
            <scale>1 1 1</scale>
            <uri>model://nj_220_2_7_gazebo/meshes/motor_50.STL</uri>
          </mesh>
        </geometry>
      </visual>
      <visual name='link_3_fixed_joint_lump__motor_6_visual_3'>
        <pose>-0.1675 0.155 0.34577 -1.5708 0 1.5708</pose>
        <geometry>
          <mesh>
            <scale>1 1 1</scale>
            <uri>model://nj_220_2_7_gazebo/meshes/motor_50.STL</uri>
          </mesh>
        </geometry>
      </visual>
      <self_collide>0</self_collide>
      <gravity>1</gravity>
    </link>
    <joint name='joint_4' type='revolute'>
      <pose relative_to='link_3'>0.105 0 0.25 0 -0 0</pose>
      <parent>link_3</parent>
      <child>link_4</child>
      <axis>
        <xyz>1 0 0</xyz>
        <limit>
          <lower>-6.28319</lower>
          <upper>6.28319</upper>
          <effort>1230</effort>
          <velocity>2.26893</velocity>
        </limit>
        <dynamics>
          <spring_reference>0</spring_reference>
          <spring_stiffness>0</spring_stiffness>
        </dynamics>
      </axis>
    </joint>
    <link name='link_4'>
      <pose relative_to='joint_4'>0 0 0 0 -0 0</pose>
      <inertial>
        <pose>0.71228 -0.02567 -3e-05 0 -0 0</pose>
        <mass>90.963</mass>
        <inertia>
          <ixx>0.689292</ixx>
          <ixy>-2.39235</ixy>
          <ixz>-0.0019259</ixz>
          <iyy>58.1199</iyy>
          <iyz>-0.00017654</iyz>
          <izz>58.2982</izz>
        </inertia>
      </inertial>
      <collision name='link_4_collision'>
        <pose>0 0 0 0 -0 0</pose>
        <geometry>
          <mesh>
            <scale>1 1 1</scale>
            <uri>model://nj_220_2_7_gazebo/meshes/link_4.STL</uri>
          </mesh>
        </geometry>
        <surface>
          <contact>
            <ode/>
          </contact>
          <friction>
            <ode/>
          </friction>
        </surface>
      </collision>
      <visual name='link_4_visual'>
        <pose>0 0 0 0 -0 0</pose>
        <geometry>
          <mesh>
            <scale>1 1 1</scale>
            <uri>model://nj_220_2_7_gazebo/meshes/link_4.STL</uri>
          </mesh>
        </geometry>
        <material>
          <script>
            <name>Gazebo/Grey</name>
            <uri>file://media/materials/scripts/gazebo.material</uri>
          </script>
        </material>
      </visual>
      <self_collide>0</self_collide>
      <gravity>1</gravity>
    </link>
    <joint name='joint_5' type='revolute'>
      <pose relative_to='link_4'>1.02033 0 0 0 -0 0</pose>
      <parent>link_4</parent>
      <child>link_5</child>
      <axis>
        <xyz>0 1 0</xyz>
        <limit>
          <lower>-2.1816</lower>
          <upper>2.1816</upper>
          <effort>1230</effort>
          <velocity>2.26893</velocity>
        </limit>
        <dynamics>
          <spring_reference>0</spring_reference>
          <spring_stiffness>0</spring_stiffness>
        </dynamics>
      </axis>
    </joint>
    <link name='link_5'>
      <pose relative_to='joint_5'>0 0 0 0 -0 0</pose>
      <inertial>
        <pose>0.09375 0.01506 2e-05 0 -0 0</pose>
        <mass>50.615</mass>
        <inertia>
          <ixx>0.679744</ixx>
          <ixy>0.0450897</ixy>
          <ixz>9.98e-05</ixz>
          <iyy>0.8323</iyy>
          <iyz>0.00011851</iyz>
          <izz>1.32231</izz>
        </inertia>
      </inertial>
      <collision name='link_5_collision'>
        <pose>0 0 0 0 -0 0</pose>
        <geometry>
          <mesh>
            <scale>1 1 1</scale>
            <uri>model://nj_220_2_7_gazebo/meshes/link_5.STL</uri>
          </mesh>
        </geometry>
        <surface>
          <contact>
            <ode/>
          </contact>
          <friction>
            <ode/>
          </friction>
        </surface>
      </collision>
      <visual name='link_5_visual'>
        <pose>0 0 0 0 -0 0</pose>
        <geometry>
          <mesh>
            <scale>1 1 1</scale>
            <uri>model://nj_220_2_7_gazebo/meshes/link_5.STL</uri>
          </mesh>
        </geometry>
        <material>
          <script>
            <name>Gazebo/DarkGrey</name>
            <uri>file://media/materials/scripts/gazebo.material</uri>
          </script>
        </material>
      </visual>
      <self_collide>0</self_collide>
      <gravity>1</gravity>
    </link>
    <joint name='joint_6' type='revolute'>
      <pose relative_to='link_5'>0.2085 0 0 0 -0 0</pose>
      <parent>link_5</parent>
      <child>link_6</child>
      <axis>
        <xyz>1 0 0</xyz>
        <limit>
          <lower>-6.28319</lower>
          <upper>6.28319</upper>
          <effort>712</effort>
          <velocity>3.40339</velocity>
        </limit>
        <dynamics>
          <spring_reference>0</spring_reference>
          <spring_stiffness>0</spring_stiffness>
        </dynamics>
      </axis>
    </joint>
    <link name='link_6'>
      <pose relative_to='joint_6'>0 0 0 0 -0 0</pose>
      <inertial>
        <pose>0.005859 -0.00061 -6e-05 0 -0 0</pose>
        <mass>5.3437</mass>
        <inertia>
          <ixx>0.029136</ixx>
          <ixy>-8.22e-06</ixy>
          <ixz>-8.6e-07</ixz>
          <iyy>0.01533</iyy>
          <iyz>5.85e-06</iyz>
          <izz>0.0151887</izz>
        </inertia>
      </inertial>
      <collision name='link_6_collision'>
        <pose>0 0 0 0 -0 0</pose>
        <geometry>
          <mesh>
            <scale>1 1 1</scale>
            <uri>model://nj_220_2_7_gazebo/meshes/link_6.STL</uri>
          </mesh>
        </geometry>
        <surface>
          <contact>
            <ode/>
          </contact>
          <friction>
            <ode/>
          </friction>
        </surface>
      </collision>
      <visual name='link_6_visual'>
        <pose>0 0 0 0 -0 0</pose>
        <geometry>
          <mesh>
            <scale>1 1 1</scale>
            <uri>model://nj_220_2_7_gazebo/meshes/link_6.STL</uri>
          </mesh>
        </geometry>
        <material>
          <script>
            <name>Gazebo/Black</name>
            <uri>file://media/materials/scripts/gazebo.material</uri>
          </script>
        </material>
      </visual>
      <self_collide>0</self_collide>
      <gravity>1</gravity>
    </link>
    <joint name='link_6_to_flange' type='fixed'>
      <pose relative_to='link_6'>0 0 -0.0395 0 -0 0</pose>
      <parent>link_6</parent>
      <child>flange</child>
      <axis>
        <dynamics>
          <spring_reference>0</spring_reference>
          <spring_stiffness>0</spring_stiffness>
        </dynamics>
        <xyz>0 0 1</xyz>
        <limit>
          <lower>-1e+16</lower>
          <upper>1e+16</upper>
        </limit>
      </axis>
      <physics>
        <provide_feedback>1</provide_feedback>
        <ode>
          <limit>
            <cfm>0</cfm>
            <erp>0.2</erp>
          </limit>
          <provide_feedback>1</provide_feedback>
        </ode>
      </physics>
    </joint>
    <link name='flange'>
      <pose relative_to='link_6_to_flange'>0 0 0 0 -0 0</pose>
      <inertial>
        <pose>0 0 0 0 -0 0</pose>
        <mass>0.01</mass>
        <inertia>
          <ixx>1e-05</ixx>
          <ixy>0</ixy>
          <ixz>0</ixz>
          <iyy>1e-05</iyy>
          <iyz>0</iyz>
          <izz>0</izz>
        </inertia>
      </inertial>
    </link>
    <joint name='joint_3' type='revolute'>
      <pose relative_to='link_1'>0.4 -0.1945 0.499 1.5708 0.087266 -3.14159</pose>
      <parent>link_1</parent>
      <child>link_2_1</child>
      <axis>
        <xyz>0 0 -1</xyz>
        <limit>
          <lower>-4.46804</lower>
          <upper>0.174533</upper>
          <effort>100000</effort>
          <velocity>1.91986</velocity>
        </limit>
        <dynamics>
          <spring_reference>0</spring_reference>
          <spring_stiffness>0</spring_stiffness>
        </dynamics>
      </axis>
    </joint>
    <link name='link_2_1'>
      <pose relative_to='joint_3'>0 0 0 0 -0 0</pose>
      <inertial>
        <pose>0.14943 -0.006379 0.023924 0 -0 0</pose>
        <mass>41.905</mass>
        <inertia>
          <ixx>0.185206</ixx>
          <ixy>-0.0706405</ixy>
          <ixz>0.172186</ixz>
          <iyy>1.70899</iyy>
          <iyz>-0.00657138</iyz>
          <izz>1.77578</izz>
        </inertia>
      </inertial>
      <collision name='link_2_1_collision'>
        <pose>0 0 0 0 -0 0</pose>
        <geometry>
          <mesh>
            <scale>1 1 1</scale>
            <uri>model://nj_220_2_7_gazebo/meshes/link_2_1.STL</uri>
          </mesh>
        </geometry>
        <surface>
          <contact>
            <ode/>
          </contact>
          <friction>
            <ode/>
          </friction>
        </surface>
      </collision>
      <visual name='link_2_1_visual'>
        <pose>0 0 0 0 -0 0</pose>
        <geometry>
          <mesh>
            <scale>1 1 1</scale>
            <uri>model://nj_220_2_7_gazebo/meshes/link_2_1.STL</uri>
          </mesh>
        </geometry>
        <material>
          <script>
            <name>Gazebo/Grey</name>
            <uri>file://media/materials/scripts/gazebo.material</uri>
          </script>
        </material>
      </visual>
      <self_collide>0</self_collide>
      <gravity>1</gravity>
    </link>
    <joint name='joint_2_1' type='revolute'>
      <pose relative_to='link_2_1'>0.35 0 0.015 0 -0 0.087266</pose>
      <parent>link_2_1</parent>
      <child>link_2_2_virtual</child>
      <axis>
        <xyz>0 0 1</xyz>
        <limit>
          <lower>-1e+16</lower>
          <upper>1e+16</upper>
        </limit>
        <dynamics>
          <spring_reference>0</spring_reference>
          <spring_stiffness>0</spring_stiffness>
        </dynamics>
      </axis>
    </joint>
    <link name='link_2_2_virtual'>
      <pose relative_to='joint_2_1'>0 0 0 0 -0 0</pose>
      <inertial>
        <pose>0 0 0 0 -0 0</pose>
        <mass>0.01</mass>
        <inertia>
          <ixx>1e-05</ixx>
          <ixy>0</ixy>
          <ixz>0</ixz>
          <iyy>1e-05</iyy>
          <iyz>0</iyz>
          <izz>0</izz>
        </inertia>
      </inertial>
    </link>
    <joint name='joint_2_2' type='revolute'>
      <pose relative_to='link_2_2_virtual'>0 0 0 0 -0 0</pose>
      <parent>link_2_2_virtual</parent>
      <child>link_2_2</child>
      <axis>
        <xyz>0 0 1</xyz>
        <limit>
          <lower>-1e+16</lower>
          <upper>1e+16</upper>
        </limit>
        <dynamics>
          <spring_reference>0</spring_reference>
          <spring_stiffness>0</spring_stiffness>
        </dynamics>
      </axis>
    </joint>
    <link name='link_2_2'>
      <pose relative_to='joint_2_2'>0 0 0 0 -0 0</pose>
      <inertial>
        <pose>0.06443 0.51885 0.01485 0 -0 0</pose>
        <mass>60.72</mass>
        <inertia>
          <ixx>21.9394</ixx>
          <ixy>1.8919</ixy>
          <ixz>0.0573372</ixz>
          <iyy>0.410289</iyy>
          <iyz>0.470647</iyz>
          <izz>22.2704</izz>
        </inertia>
      </inertial>
      <collision name='link_2_2_collision'>
        <pose>0 0 0 0 -0 0</pose>
        <geometry>
          <mesh>
            <scale>1 1 1</scale>
            <uri>model://nj_220_2_7_gazebo/meshes/link_2_2.STL</uri>
          </mesh>
        </geometry>
        <surface>
          <contact>
            <ode/>
          </contact>
          <friction>
            <ode/>
          </friction>
        </surface>
      </collision>
      <visual name='link_2_2_visual'>
        <pose>0 0 0 0 -0 0</pose>
        <geometry>
          <mesh>
            <scale>1 1 1</scale>
            <uri>model://nj_220_2_7_gazebo/meshes/link_2_2.STL</uri>
          </mesh>
        </geometry>
        <material>
          <script>
            <name>Gazebo/Grey</name>
            <uri>file://media/materials/scripts/gazebo.material</uri>
          </script>
        </material>
      </visual>
      <self_collide>0</self_collide>
      <gravity>1</gravity>
    </link>
    <joint name='joint_2_3' type='revolute'>
      <pose relative_to='link_2_2'>0 1.175 0 1.5708 -0 -3.14159</pose>
      <parent>link_2_2</parent>
      <child>link_2_3</child>
      <axis>
        <xyz>0 0 1</xyz>
        <limit>
          <lower>-6.28319</lower>
          <upper>6.28319</upper>
          <effort>712</effort>
          <velocity>3.40339</velocity>
        </limit>
        <dynamics>
          <spring_reference>0</spring_reference>
          <spring_stiffness>0</spring_stiffness>
        </dynamics>
      </axis>
    </joint>
    <link name='link_2_3'>
      <pose relative_to='joint_2_3'>0 0 0 0 -0 0</pose>
      <inertial>
        <pose>0 0 0 0 -0 0</pose>
        <mass>0.01</mass>
        <inertia>
          <ixx>1e-05</ixx>
          <ixy>0</ixy>
          <ixz>0</ixz>
          <iyy>1e-05</iyy>
          <iyz>0</iyz>
          <izz>0</izz>
        </inertia>
      </inertial>
      <visual name='link_2_3_visual'>
        <pose>0 0 0 0 -0 0</pose>
        <geometry>
          <box>
            <size>0.05 0.05 0.5</size>
          </box>
        </geometry>
        <material>
          <script>
            <name>Gazebo/Grey</name>
            <uri>file://media/materials/scripts/gazebo.material</uri>
          </script>
        </material>
      </visual>
      <self_collide>0</self_collide>
      <gravity>1</gravity>
    </link>
    <joint name='closing_joint' type='revolute'>
      <parent>link_3</parent>
      <child>link_2_3</child>
      <pose relative_to='link_3'>0 0 0 0 -0 0</pose>
      <axis>
        <xyz>0 1 0</xyz>
        <limit>
          <lower>-1e+16</lower>
          <upper>1e+16</upper>
        </limit>
      </axis>
    </joint>
    <plugin name='gazebo_ros_control' filename='libgazebo_ros_control.so'>
      <robotNamespace>/nj_220_2_7</robotNamespace>
      <robotSimType>gazebo_ros_control/DefaultRobotHWSim</robotSimType>
    </plugin>
    <plugin name='ft_sensor' filename='libgazebo_ros_ft_sensor.so'>
      <updateRate>1000.0</updateRate>
      <topicName>gripper/wrench</topicName>
      <jointName>link_6_to_flange</jointName>
    </plugin>
    <frame name='joint_external_piece' attached_to='link_1'>
      <pose>0 0 0 0 -0 0</pose>
    </frame>
    <frame name='external_piece' attached_to='joint_external_piece'/>
    <frame name='joint_motor_1' attached_to='link_1'>
      <pose>-0.1567 0.0905 0.12075 0 -0 -2.08916</pose>
    </frame>
    <frame name='motor_1' attached_to='joint_motor_1'/>
    <frame name='joint_motor_2' attached_to='link_1'>
      <pose>0.4 0.2955 0.499 1.57079 1.57079 3.14159</pose>
    </frame>
    <frame name='motor_2' attached_to='joint_motor_2'/>
    <frame name='joint_motor_3' attached_to='link_1'>
      <pose>0.4 -0.358 0.499 -1.57079 1.57079 3.14159</pose>
    </frame>
    <frame name='motor_3' attached_to='joint_motor_3'/>
    <frame name='joint_motor_4' attached_to='link_3'>
      <pose>-0.2 0.21052 0.175 3e-06 1.57079 3.14159</pose>
    </frame>
    <frame name='motor_4' attached_to='joint_motor_4'/>
    <frame name='joint_motor_5' attached_to='link_3'>
      <pose>-0.1675 0 0.25 1.5708 0 -1.5708</pose>
    </frame>
    <frame name='motor_5' attached_to='joint_motor_5'/>
    <static>0</static>
    <frame name='joint_motor_6' attached_to='link_3'>
      <pose>-0.1675 0.155 0.34577 -1.5708 0 1.5708</pose>
    </frame>
    <frame name='motor_6' attached_to='joint_motor_6'/>
  </model>
</sdf>
